Workbook

Sheet Tong_quan
A1: Master schedule
A2: Xây dựng và triển khai hệ thống website bán hàng trực tuyến (Web Selling Site System)
F3: Ngày nghỉ
A4: Ngày bắt đầu | B4: 46464 | F4: 46493
A5: Ngày cut over | B5: 46597 | F5: 46507
A6: Số ngày làm việc | B6: =NETWORKDAYS(B4,B5,$F$4:$F$40) -> 93 | F6: 46510
A7: Tổng khối lượng, MD | B7: =SUMIFS(Lich_trinh!D:D,Lich_trinh!C:C,1) -> 733
A8: Quỹ thời gian, MD | B8: =SUM(Phan_bo!E:E) -> 908
A9: Tỷ lệ sử dụng quỹ | B9: =IF(B8=0,0,B7/B8) -> 0.80726872
A10: Hoàn thành giai đoạn Thực hiện (không tính gói dàn trải và gói Kết thúc) | B10: 46597
A11: Dự trữ đến cut over, ngày làm việc (trước các gói gắn ngày cố định) | B11: 7
A12: Số sprint | B12: =COUNTIFS(Sprint!A:A,"S*",Sprint!A:A,"<>Sprint") -> 9
A13: Đường găng theo phụ thuộc, ngày | B13: 51
A14: Ngưỡng tỷ lệ sử dụng quỹ tối thiểu | B14: 0.8
A15: Ngày đóng dự án (hết giai đoạn Kết thúc) | B15: 46611
A16: Chữ xanh dương: dữ liệu do bước lập lịch tính từ WBS, giao việc và lịch làm việc. Chữ đen: công thức. Không sửa tay dữ liệu xanh dương. Khi cần thay đổi, sửa đầu vào (WBS, giao việc, mốc) và lập lại lịch.

Sheet Lich_trinh
A1: Lịch trình theo WBS
O3: 46461 | P3: 46468 | Q3: 46475 | R3: 46482 | S3: 46489 | T3: 46496 | U3: 46503 | V3: 46510 | W3: 46517 | X3: 46524 | Y3: 46531 | Z3: 46538 | AA3: 46545 | AB3: 46552 | AC3: 46559 | AD3: 46566 | AE3: 46573 | AF3: 46580 | AG3: 46587 | AH3: 46594 | AI3: 46601 | AJ3: 46608
A4: Mã WBS | B4: Tên công việc | C4: Mức | D4: MD | E4: Người thực hiện | F4: Bắt đầu | G4: Kết thúc | H4: Số ngày làm việc | I4: Giai đoạn | J4: Sprint | K4: Phụ thuộc | L4: Đường găng | M4: Mục cha | N4: Ràng buộc ngày | O4: T1 | P4: T2 | Q4: T3 | R4: T4 | S4: T5 | T4: T6 | U4: T7 | V4: T8 | W4: T9 | X4: T10 | Y4: T11 | Z4: T12 | AA4: T13 | AB4: T14 | AC4: T15 | AD4: T16 | AE4: T17 | AF4: T18 | AG4: T19 | AH4: T20 | AI4: T21 | AJ4: T22
A5: 1 | B5: Phân hệ quản lý sản phẩm | C5: 1 | D5: =SUMIFS(D:D,M:M,A5) -> 151 | F5: =_xlfn.MINIFS(F:F,M:M,A5) -> 46464 | G5: =_xlfn.MAXIFS(G:G,M:M,A5) -> 46603 | H5: =NETWORKDAYS(F5,G5,Tong_quan!$F$4:$F$40) -> 97 | I5: Khởi động, Suốt dự án, S1-S9, Kết thúc
A6: 1.1 | B6: Quản lý dự án, phần phân bổ cho phân hệ quản lý sản phẩm | C6: 2 | D6: =SUMIFS(D:D,M:M,A6) -> 14 | F6: =_xlfn.MINIFS(F:F,M:M,A6) -> 46464 | G6: =_xlfn.MAXIFS(G:G,M:M,A6) -> 46603 | H6: =NETWORKDAYS(F6,G6,Tong_quan!$F$4:$F$40) -> 97 | I6: Khởi động, Suốt dự án, Kết thúc | M6: 1
A7: 1.1.1 | B7: Họp khởi động, xác nhận phạm vi, điều kiện tiền đề, vai trò và trách nhiệm các bên | C7: 3 | D7: 2 | E7: Trần Bá Đạt | F7: 46464 | G7: 46469 | H7: =NETWORKDAYS(F7,G7,Tong_quan!$F$4:$F$40) -> 4 | I7: Khởi động | M7: 1.1
A8: 1.1.2 | B8: Họp tiến độ hằng tuần, trình diễn và báo cáo cuối sprint, phần phân hệ quản lý sản phẩm | C8: 3 | D8: 4 | E8: Trần Bá Đạt (dàn trải) | F8: 46464 | G8: 46597 | H8: =NETWORKDAYS(F8,G8,Tong_quan!$F$4:$F$40) -> 93 | I8: Suốt dự án | M8: 1.1
A9: 1.1.3 | B9: Quản lý rủi ro, vấn đề và yêu cầu thay đổi đặc tả, phần phân hệ quản lý sản phẩm | C9: 3 | D9: 3 | E9: Trần Bá Đạt (dàn trải) | F9: 46464 | G9: 46597 | H9: =NETWORKDAYS(F9,G9,Tong_quan!$F$4:$F$40) -> 93 | I9: Suốt dự án | M9: 1.1
A10: 1.1.4 | B10: Quản lý cấu hình, phiên bản tài liệu, hồ sơ dự án, hồ sơ nghiệm thu và thanh toán, phần phân hệ quản lý sản phẩm | C10: 3 | D10: 3 | E10: Trần Bá Đạt (dàn trải) | F10: 46464 | G10: 46597 | H10: =NETWORKDAYS(F10,G10,Tong_quan!$F$4:$F$40) -> 93 | I10: Suốt dự án | M10: 1.1
A11: 1.1.5 | B11: Báo cáo tổng kết, bài học kinh nghiệm và bàn giao hồ sơ dự án | C11: 3 | D11: 2 | E11: Trần Bá Đạt | F11: 46598 | G11: 46603 | H11: =NETWORKDAYS(F11,G11,Tong_quan!$F$4:$F$40) -> 4 | I11: Kết thúc | K11: 4.4.5 | M11: 1.1
A12: 1.2 | B12: Phân tích và thiết kế phân hệ quản lý sản phẩm | C12: 2 | D12: =SUMIFS(D:D,M:M,A12) -> 32 | F12: =_xlfn.MINIFS(F:F,M:M,A12) -> 46470 | G12: =_xlfn.MAXIFS(G:G,M:M,A12) -> 46517 | H12: =NETWORKDAYS(F12,G12,Tong_quan!$F$4:$F$40) -> 31 | I12: Thực hiện | J12: S1-S4 | M12: 1
A13: 1.2.1 | B13: Đặc tả chức năng (Function) tìm kiếm và hiển thị sản phẩm | C13: 3 | D13: 4 | E13: Nguyễn Hoàng Nam, Trần Bá Đạt | F13: 46470 | G13: 46472 | H13: =NETWORKDAYS(F13,G13,Tong_quan!$F$4:$F$40) -> 3 | I13: Thực hiện | J13: S1 | K13: 3.2.1 | M13: 1.2
A14: 1.2.2 | B14: Sơ đồ phân cấp menu (Menu Layer) | C14: 3 | D14: 3 | E14: Nguyễn Hoàng Nam | F14: 46478 | G14: 46482 | H14: =NETWORKDAYS(F14,G14,Tong_quan!$F$4:$F$40) -> 3 | I14: Thực hiện | J14: S2 | K14: 1.2.1 | M14: 1.2
A15: 1.2.3 | B15: Thiết kế giao diện ưu tiên trang chủ, tìm kiếm và chi tiết sản phẩm | C15: 3 | D15: 4 | E15: Vũ Đức Minh, Lê Quang Huy | F15: 46483 | G15: 46484 | H15: =NETWORKDAYS(F15,G15,Tong_quan!$F$4:$F$40) -> 2 | I15: Thực hiện | J15: S2 | K15: 1.2.2, 2.2.3 | M15: 1.2
A16: 1.2.4 | B16: Thư viện thành phần giao diện dùng chung, tương thích thiết bị di động | C16: 3 | D16: 4 | E16: Vũ Đức Minh | F16: 46485 | G16: 46490 | H16: =NETWORKDAYS(F16,G16,Tong_quan!$F$4:$F$40) -> 4 | I16: Thực hiện | J16: S2 | K16: 1.2.3, 4.3.3 | M16: 1.2
A17: 1.2.5 | B17: Đặc tả use case tìm kiếm, lọc và sắp xếp sản phẩm | C17: 3 | D17: 5 | E17: Nguyễn Hoàng Nam | F17: 46483 | G17: 46490 | H17: =NETWORKDAYS(F17,G17,Tong_quan!$F$4:$F$40) -> 6 | I17: Thực hiện | J17: S2 | K17: 1.2.1 | M17: 1.2
A18: 1.2.6 | B18: Đặc tả use case trang chủ, danh mục và chi tiết sản phẩm | C18: 3 | D18: 3 | E18: Nguyễn Thị Phương Liên | F18: 46496 | G18: 46498 | H18: =NETWORKDAYS(F18,G18,Tong_quan!$F$4:$F$40) -> 3 | I18: Thực hiện | J18: S3 | K18: 1.2.1, 1.2.2 | M18: 1.2
A19: 1.2.7 | B19: Thiết kế chi tiết tìm kiếm, lọc, sắp xếp và chỉ mục tìm kiếm | C19: 3 | D19: 5 | E19: Ninh Đức Toàn | F19: 46491 | G19: 46498 | H19: =NETWORKDAYS(F19,G19,Tong_quan!$F$4:$F$40) -> 5 | I19: Thực hiện | J19: S2-S3 | K19: 1.2.1, 4.2.3, 1.2.5 | M19: 1.2
A20: 1.2.8 | B20: Thiết kế chi tiết trang chủ, danh mục và chi tiết sản phẩm | C20: 3 | D20: 4 | E20: Trần Bá Đạt | F20: 46504 | G20: 46517 | H20: =NETWORKDAYS(F20,G20,Tong_quan!$F$4:$F$40) -> 8 | I20: Thực hiện | J20: S3-S4 | K20: 1.2.1, 1.2.2, 4.2.3, 1.2.6 | M20: 1.2
A21: 1.3 | B21: Xây dựng phân hệ quản lý sản phẩm (lập trình và kiểm thử đơn vị) | C21: 2 | D21: =SUMIFS(D:D,M:M,A21) -> 39 | F21: =_xlfn.MINIFS(F:F,M:M,A21) -> 46504 | G21: =_xlfn.MAXIFS(G:G,M:M,A21) -> 46538 | H21: =NETWORKDAYS(F21,G21,Tong_quan!$F$4:$F$40) -> 23 | I21: Thực hiện | J21: S3-S5 | M21: 1
A22: 1.3.1 | B22: Dịch vụ chỉ mục tìm kiếm và cập nhật chỉ mục từ Selling DB | C22: 3 | D22: 5 | E22: Trương Quốc Việt | F22: 46504 | G22: 46513 | H22: =NETWORKDAYS(F22,G22,Tong_quan!$F$4:$F$40) -> 6 | I22: Thực hiện | J22: S3 | K22: 1.2.7, 4.3.2 | M22: 1.3
A23: 1.3.2 | B23: Dịch vụ tìm kiếm theo từ khóa và gợi ý tìm kiếm | C23: 3 | D23: 5 | E23: Phạm Tuấn Anh | F23: 46517 | G23: 46521 | H23: =NETWORKDAYS(F23,G23,Tong_quan!$F$4:$F$40) -> 5 | I23: Thực hiện | J23: S4 | K23: 1.2.7, 4.3.2 | M23: 1.3
A24: 1.3.3 | B24: Dịch vụ lọc và sắp xếp kết quả tìm kiếm | C24: 3 | D24: 5 | E24: Trương Quốc Việt | F24: 46513 | G24: 46520 | H24: =NETWORKDAYS(F24,G24,Tong_quan!$F$4:$F$40) -> 6 | I24: Thực hiện | J24: S3-S4 | K24: 1.2.7, 4.3.2 | M24: 1.3
A25: 1.3.4 | B25: Dịch vụ danh mục, chi tiết sản phẩm, biến thể, tồn kho và giá khuyến mại hiển thị | C25: 3 | D25: 6 | E25: Đỗ Minh Quân, Lê Quang Huy | F25: 46520 | G25: 46528 | H25: =NETWORKDAYS(F25,G25,Tong_quan!$F$4:$F$40) -> 7 | I25: Thực hiện | J25: S4-S5 | K25: 1.2.8, 4.3.2 | M25: 1.3
A26: 1.3.5 | B26: Giao diện trang chủ và điều hướng danh mục theo Menu Layer | C26: 3 | D26: 4 | E26: Nguyễn Hoàng Nam | F26: 46526 | G26: 46531 | H26: =NETWORKDAYS(F26,G26,Tong_quan!$F$4:$F$40) -> 4 | I26: Thực hiện | J26: S4-S5 | K26: 1.2.8, 1.2.4 | M26: 1.3
A27: 1.3.6 | B27: Giao diện tìm kiếm, kết quả và bộ lọc | C27: 3 | D27: 5 | E27: Lê Quang Huy, Bùi Anh Tuấn | F27: 46514 | G27: 46520 | H27: =NETWORKDAYS(F27,G27,Tong_quan!$F$4:$F$40) -> 5 | I27: Thực hiện | J27: S4 | K27: 1.2.7, 1.2.4 | M27: 1.3
A28: 1.3.7 | B28: Giao diện chi tiết sản phẩm | C28: 3 | D28: 5 | E28: Lê Quang Huy | F28: 46525 | G28: 46534 | H28: =NETWORKDAYS(F28,G28,Tong_quan!$F$4:$F$40) -> 8 | I28: Thực hiện | J28: S4-S5 | K28: 1.2.8, 1.2.4 | M28: 1.3
A29: 1.3.8 | B29: Bộ nhớ đệm và tối ưu thời gian phản hồi trang danh mục, chi tiết sản phẩm | C29: 3 | D29: 4 | E29: Phạm Tuấn Anh, Đỗ Minh Quân | F29: 46531 | G29: 46538 | H29: =NETWORKDAYS(F29,G29,Tong_quan!$F$4:$F$40) -> 6 | I29: Thực hiện | J29: S5 | K29: 1.3.4 | M29: 1.3
A30: 1.4 | B30: Kiểm thử phân hệ quản lý sản phẩm, gồm phần kiểm thử hệ thống và kiểm thử chấp nhận phân bổ | C30: 2 | D30: =SUMIFS(D:D,M:M,A30) -> 54 | F30: =_xlfn.MINIFS(F:F,M:M,A30) -> 46517 | G30: =_xlfn.MAXIFS(G:G,M:M,A30) -> 46595 | H30: =NETWORKDAYS(F30,G30,Tong_quan!$F$4:$F$40) -> 57 | I30: Thực hiện | J30: S4-S9 | M30: 1
A31: 1.4.1 | B31: Kịch bản kiểm thử và bộ kiểm thử tự động phân hệ quản lý sản phẩm | C31: 3 | D31: 6 | E31: Vũ Đức Minh, Ninh Đức Toàn | F31: 46517 | G31: 46525 | H31: =NETWORKDAYS(F31,G31,Tong_quan!$F$4:$F$40) -> 7 | I31: Thực hiện | J31: S4 | K31: 1.2.5, 1.2.6 | M31: 1.4
A32: 1.4.2 | B32: Kiểm thử tìm kiếm, lọc và sắp xếp sản phẩm | C32: 3 | D32: 7 | E32: Nguyễn Thị Phương Liên | F32: 46526 | G32: 46535 | H32: =NETWORKDAYS(F32,G32,Tong_quan!$F$4:$F$40) -> 8 | I32: Thực hiện | J32: S4-S5 | K32: 1.4.1, 1.3.1, 1.3.2, 1.3.3, 1.3.6 | M32: 1.4
A33: 1.4.3 | B33: Kiểm thử trang chủ, danh mục và chi tiết sản phẩm | C33: 3 | D33: 6 | E33: Nguyễn Thị Phương Liên, Ninh Đức Toàn, Phạm Ngọc Anh | F33: 46542 | G33: 46553 | H33: =NETWORKDAYS(F33,G33,Tong_quan!$F$4:$F$40) -> 8 | I33: Thực hiện | J33: S6 | K33: 1.4.1, 1.3.4, 1.3.5, 1.3.7, 1.3.8 | M33: 1.4
A34: 1.4.4 | B34: Sửa lỗi và kiểm thử lại chức năng tìm kiếm, lọc và sắp xếp | C34: 3 | D34: 3 | E34: Lê Quang Huy | F34: 46538 | G34: 46540 | H34: =NETWORKDAYS(F34,G34,Tong_quan!$F$4:$F$40) -> 3 | I34: Thực hiện | J34: S5 | K34: 1.4.2 | M34: 1.4
A35: 1.4.5 | B35: Kiểm thử tương thích trình duyệt, thiết bị di động và thời gian phản hồi phân hệ quản lý sản phẩm | C35: 3 | D35: 5 | E35: Vũ Đức Minh, Ninh Đức Toàn | F35: 46540 | G35: 46548 | H35: =NETWORKDAYS(F35,G35,Tong_quan!$F$4:$F$40) -> 7 | I35: Thực hiện | J35: S5-S6 | K35: 1.4.1, 1.3.5, 1.3.6, 1.3.7, 1.3.8 | M35: 1.4
A36: 1.4.6 | B36: Sửa lỗi và kiểm thử lại trang chủ, danh mục và chi tiết sản phẩm | C36: 3 | D36: 3 | E36: Đỗ Minh Quân | F36: 46566 | G36: 46568 | H36: =NETWORKDAYS(F36,G36,Tong_quan!$F$4:$F$40) -> 3 | I36: Thực hiện | J36: S7 | K36: 1.4.3, 1.4.5 | M36: 1.4
A37: 1.4.7 | B37: Tài liệu chức năng và nghiệm thu nội bộ phân hệ quản lý sản phẩm | C37: 3 | D37: 3 | E37: Nguyễn Hoàng Nam | F37: 46574 | G37: 46576 | H37: =NETWORKDAYS(F37,G37,Tong_quan!$F$4:$F$40) -> 3 | I37: Thực hiện | J37: S8 | K37: 1.4.4, 1.4.6 | M37: 1.4
A38: 1.4.8 | B38: Kịch bản và công cụ kiểm thử hiệu năng, chịu tải 500 người dùng đồng thời | C38: 3 | D38: 4 | E38: Vũ Đức Minh, Nguyễn Thị Phương Liên | F38: 46545 | G38: 46554 | H38: =NETWORKDAYS(F38,G38,Tong_quan!$F$4:$F$40) -> 8 | I38: Thực hiện | J38: S6 | K38: 2.4.8 | M38: 1.4
A39: 1.4.9 | B39: Kiểm thử hiệu năng trên môi trường kiểm thử | C39: 3 | D39: 3 | E39: Phạm Ngọc Anh | F39: 46555 | G39: 46559 | H39: =NETWORKDAYS(F39,G39,Tong_quan!$F$4:$F$40) -> 3 | I39: Thực hiện | J39: S6-S7 | K39: 1.4.8, 1.3.8, 4.5.1 | M39: 1.4
A40: 1.4.10 | B40: Tối ưu hiệu năng và khắc phục lỗ hổng theo kết quả kiểm thử bản phát hành | C40: 3 | D40: 4 | E40: Trương Quốc Việt | F40: 46590 | G40: 46595 | H40: =NETWORKDAYS(F40,G40,Tong_quan!$F$4:$F$40) -> 4 | I40: Thực hiện | J40: S9 | K40: 4.4.7 | M40: 1.4
A41: 1.4.11 | B41: Tổ chức và hỗ trợ kiểm thử chấp nhận cùng Chủ đầu tư luồng tìm kiếm và hiển thị sản phẩm | C41: 3 | D41: 4 | E41: Trần Thu Hà | F41: 46584 | G41: 46595 | H41: =NETWORKDAYS(F41,G41,Tong_quan!$F$4:$F$40) -> 8 | I41: Thực hiện | J41: S9 | K41: 3.4.11, 4.4.5, 3.5.1 | L41: Có | M41: 1.4 | N41: Kiểm thử chấp nhận 16/07/2027 - 27/07/2027, trong khoảng cam kết CK6 16/07/2027 - 27/07/2027
...

Sheet Sprint
A1: Sprint | B1: Từ ngày | C1: Đến ngày | D1: Số ngày làm việc | E1: MD kế hoạch | F1: Quỹ thời gian, MD | G1: Tỷ lệ sử dụng | H1: Mục tiêu | I1: Sản phẩm trình diễn
A2: S1 | B2: 46464 | C2: 46477 | D2: =NETWORKDAYS(B2,C2,Tong_quan!$F$4:$F$40) -> 10 | E2: =SUMIFS(Phan_bo!D:D,Phan_bo!C:C,A2) -> 54.29 | F2: =SUMIFS(Phan_bo!E:E,Phan_bo!C:C,A2) -> 80 | G2: =IF(F2=0,0,E2/F2) -> 0.678625 | H2: Khảo sát nghiệp vụ và hệ thống hiện có, đặc tả chức năng ba phân hệ chức năng, nghiên cứu hành vi người dùng, kiến trúc hệ thống, khung ứng dụng phía máy chủ và giao diện, dịch vụ gửi thư điện tử | I2: Báo cáo khảo sát, đặc tả chức năng ba phân hệ chức năng, kiến trúc hệ thống và khung ứng dụng phía máy chủ, giao diện
A3: S2 | B3: 46478 | C3: 46491 | D3: =NETWORKDAYS(B3,C3,Tong_quan!$F$4:$F$40) -> 10 | E3: =SUMIFS(Phan_bo!D:D,Phan_bo!C:C,A3) -> 71.76 | F3: =SUMIFS(Phan_bo!E:E,Phan_bo!C:C,A3) -> 100 | G3: =IF(F3=0,0,E3/F3) -> 0.7176 | H3: Cấu trúc, cấu hình Selling DB và tạo lập Selling DB trên môi trường phát triển, sơ đồ phân cấp menu, thiết kế giao diện ưu tiên ba nhóm chức năng, thư viện thành phần giao diện, môi trường phát triển và kiểm thử có quy trình triển khai tự động, đặc tả use case đợt đầu của ba phân hệ chức năng, thiết kế chi tiết đặt hàng | I3: Selling DB trên môi trường phát triển, sơ đồ phân cấp menu (Menu Layer), mẫu giao diện ưu tiên ba nhóm chức năng, khung ứng dụng triển khai tự động lên môi trường phát triển
A4: S3 | B4: 46492 | C4: 46513 | D4: =NETWORKDAYS(B4,C4,Tong_quan!$F$4:$F$40) -> 13 | E4: =SUMIFS(Phan_bo!D:D,Phan_bo!C:C,A4) -> 127.57 | F4: =SUMIFS(Phan_bo!E:E,Phan_bo!C:C,A4) -> 156 | G4: =IF(F4=0,0,E4/F4) -> 0.81775641 | H4: Hai bên xác nhận đặc tả yêu cầu và giao diện ưu tiên (M2), đặc tả giao diện tích hợp sau khi nhận tài liệu Main System (CK1) và thiết kế tích hợp, hoàn thành đặc tả use case và thiết kế chi tiết, chỉ mục tìm kiếm, lập trình đăng ký, đăng nhập, khôi phục mật khẩu, giỏ hàng, đặt hàng có phí vận chuyển và mã giảm giá, kịch bản kiểm thử phân hệ và kịch bản kiểm thử tích hợp | I4: Đăng ký, đăng nhập, khôi phục mật khẩu, giỏ hàng và đặt hàng có phí vận chuyển, mã giảm giá trên môi trường phát triển
A5: S4 | B5: 46514 | C5: 46527 | D5: =NETWORKDAYS(B5,C5,Tong_quan!$F$4:$F$40) -> 10 | E5: =SUMIFS(Phan_bo!D:D,Phan_bo!C:C,A5) -> 114.27 | F5: =SUMIFS(Phan_bo!E:E,Phan_bo!C:C,A5) -> 120 | G5: =IF(F5=0,0,E5/F5) -> 0.95225 | H5: Lập trình tìm kiếm, lọc và sắp xếp sản phẩm, giữ tồn kho, theo dõi đơn hàng, hủy đơn và đổi trả, dịch vụ giả lập Main System, đồng bộ tồn kho, chuyển đơn hàng và nhận trạng thái vận chuyển theo đặc tả giao diện tích hợp đã lập, Chủ đầu tư xác nhận đặc tả giao diện tích hợp, kế hoạch kiểm thử hệ thống, kiểm thử bảo mật tài khoản và kiểm thử đặt hàng, phí vận chuyển, khuyến mại | I5: Tìm kiếm, lọc và sắp xếp sản phẩm, theo dõi và hủy đơn hàng trên môi trường phát triển, chuyển đơn hàng và nhận trạng thái vận chuyển trên dịch vụ giả lập Main System
A6: S5 | B6: 46528 | C6: 46541 | D6: =NETWORKDAYS(B6,C6,Tong_quan!$F$4:$F$40) -> 10 | E6: =SUMIFS(Phan_bo!D:D,Phan_bo!C:C,A6) -> 95.67 | F6: =SUMIFS(Phan_bo!E:E,Phan_bo!C:C,A6) -> 120 | G6: =IF(F6=0,0,E6/F6) -> 0.79725 | H6: Lập trình danh mục, chi tiết sản phẩm, trang chủ, bộ nhớ đệm, trang thành viên, sổ địa chỉ và đồng ý điều khoản, đồng bộ danh mục sản phẩm và giá, chuyển đơn hàng và nhận trạng thái vận chuyển, công cụ chuyển đổi dữ liệu, kiểm thử tích hợp trên môi trường thử của Main System (CK2, CK8), kiểm thử tìm kiếm, đăng ký, đăng nhập, thông tin thành viên, giỏ hàng và luồng đặt hàng, kế hoạch kiểm thử hệ thống, môi trường vận hành (CK7), khảo sát bán hàng trên sàn thương mại điện tử (CR01) | I6: Trang chủ, danh mục, chi tiết sản phẩm, trang thành viên và luồng đặt hàng có trao đổi dữ liệu với Main System trên môi trường thử
A7: S6 | B7: 46542 | C7: 46555 | D7: =NETWORKDAYS(B7,C7,Tong_quan!$F$4:$F$40) -> 10 | E7: =SUMIFS(Phan_bo!D:D,Phan_bo!C:C,A7) -> 90.87 | F7: =SUMIFS(Phan_bo!E:E,Phan_bo!C:C,A7) -> 120 | G7: =IF(F7=0,0,E7/F7) -> 0.75725 | H7: Kiểm thử trang chủ, danh mục, chi tiết sản phẩm, tương thích trình duyệt và thiết bị, kiểm thử hiệu năng, kiểm thử theo dõi đơn hàng và đổi trả, kiểm thử khả năng sử dụng và rà soát lỗ hổng bảo mật, sửa lỗi tích hợp, kịch bản kiểm thử hệ thống đầu cuối, hướng dẫn vận hành, tài liệu hướng dẫn sử dụng, giám sát và sao lưu tự động, chuyển đổi thử dữ liệu (CK3), cùng với đặc tả, thiết kế tích hợp, kết nối sàn, đồng bộ tồn kho, nhận đơn hàng từ sàn và kịch bản kiểm thử bán hàng trên sàn (CR01) | I7: Bản phát hành đã sửa lỗi kiểm thử phân hệ, báo cáo kiểm thử hiệu năng, kết nối sàn và nhận đơn hàng từ sàn trên môi trường thử
A8: S7 | B8: 46556 | C8: 46569 | D8: =NETWORKDAYS(B8,C8,Tong_quan!$F$4:$F$40) -> 10 | E8: =SUMIFS(Phan_bo!D:D,Phan_bo!C:C,A8) -> 61.52 | F8: =SUMIFS(Phan_bo!E:E,Phan_bo!C:C,A8) -> 69 | G8: =IF(F8=0,0,E8/F8) -> 0.8915942 | H8: Kiểm thử chức năng đầu cuối, sửa lỗi và kiểm thử lại các phân hệ, kịch bản kiểm thử chấp nhận, kế hoạch cut over, diễn tập chuyển đổi dự phòng, nạp nội dung sản phẩm (CK4), cùng với xác nhận đặc tả bán hàng trên sàn, đồng bộ sản phẩm và giá, cập nhật trạng thái, đối soát, giao diện quản trị kênh sàn, tài liệu và buổi hướng dẫn sử dụng bán hàng trên sàn, kiểm thử tích hợp với sàn và bắt đầu kiểm thử hệ thống luồng bán hàng trên sàn (CR01) | I8: Báo cáo kiểm thử chức năng đầu cuối, luồng bán hàng trên sàn đầy đủ trên môi trường thử, tài liệu hướng dẫn sử dụng bán hàng trên sàn
A9: S8 | B9: 46570 | C9: 46583 | D9: =NETWORKDAYS(B9,C9,Tong_quan!$F$4:$F$40) -> 10 | E9: =SUMIFS(Phan_bo!D:D,Phan_bo!C:C,A9) -> 40.53 | F9: =SUMIFS(Phan_bo!E:E,Phan_bo!C:C,A9) -> 53 | G9: =IF(F9=0,0,E9/F9) -> 0.76471698 | H9: Khắc phục lỗi sau kiểm thử hệ thống (M4), Chủ đầu tư kiểm tra chức năng chính và tích hợp với Main System (M3), diễn tập triển khai, giám sát vận hành, cùng với hoàn thành kiểm thử hệ thống, khắc phục lỗi và kiểm thử lại phần bán hàng trên sàn, bàn giao mã nguồn phần sàn và cấu hình kết nối sàn trên môi trường vận hành (CR01) | I9: Bản phát hành sẵn sàng kiểm thử chấp nhận gồm phần bán hàng trên sàn, biên bản kiểm tra chức năng chính (M3), kết nối sàn trên môi trường vận hành
A10: S9 | B10: 46584 | C10: 46597 | D10: =NETWORKDAYS(B10,C10,Tong_quan!$F$4:$F$40) -> 10 | E10: =SUMIFS(Phan_bo!D:D,Phan_bo!C:C,A10) -> 74.52 | F10: =SUMIFS(Phan_bo!E:E,Phan_bo!C:C,A10) -> 88 | G10: =IF(F10=0,0,E10/F10) -> 0.84681818 | H10: Kiểm thử chấp nhận và kiểm thử vận hành cùng Chủ đầu tư (M5), kiểm thử chấp nhận phần bán hàng trên sàn cùng Chủ đầu tư và nghiệm thu phần sàn (M9), khắc phục lỗi trong khoảng kiểm thử chấp nhận, kiểm thử hiệu năng và an toàn trên môi trường vận hành, chuyển đổi dữ liệu chính thức, cut over 29/07/2027 (M6), bàn giao mã nguồn và hệ thống (M7) | I10: Hệ thống gồm phần bán hàng trên sàn trên môi trường vận hành, biên bản nghiệm thu phần bán hàng trên sàn (M9), biên bản kiểm thử chấp nhận và biên bản bàn giao
A11: KT | E11: =SUMIFS(Phan_bo!D:D,Phan_bo!C:C,A11) -> 2 | F11: =SUMIFS(Phan_bo!E:E,Phan_bo!C:C,A11) -> 2 | H11: Giai đoạn Kết thúc sau cut over, quỹ huy động theo tỷ lệ huy động giai đoạn Kết thúc của thành viên
A12: Tổng | D12: =SUM(D2:D11) -> 93 | E12: =SUM(E2:E11) -> 733 | F12: =SUM(F2:F11) -> 908 | G12: =IF(F12=0,0,E12/F12) -> 0.80726872

Sheet Moc
A1: Mốc | B1: Nội dung | C1: Ngày dự kiến | D1: Hạn | E1: Trạng thái | F1: Căn cứ (gói hoàn thành) | G1: Đợt thanh toán | H1: Sprint
A2: M0 | B2: Hợp đồng có hiệu lực, khởi động dự án | C2: 46464 | E2: =IF(D2="","Không có hạn",IF(C2<=D2,"Đúng hạn","Trễ hạn")) -> Không có hạn | F2: Ngày cố định | G2: 1 | H2: S1
A3: M1 | B3: Kế hoạch quản lý dự án được Chủ đầu tư xác nhận | C3: 46491 | D3: 46491 | E3: =IF(D3="","Không có hạn",IF(C3<=D3,"Đúng hạn","Trễ hạn")) -> Đúng hạn | F3: 3.1.2 | H3: S2
A4: M2 | B4: Đặc tả yêu cầu và giao diện ưu tiên được hai bên xác nhận | C4: 46513 | D4: 46517 | E4: =IF(D4="","Không có hạn",IF(C4<=D4,"Đúng hạn","Trễ hạn")) -> Đúng hạn | F4: 3.2.5 | G4: 2 | H4: S3
A5: M3 | B5: Chủ đầu tư kiểm tra đạt các chức năng chính và tích hợp với Main System | C5: 46576 | D5: 46576 | E5: =IF(D5="","Không có hạn",IF(C5<=D5,"Đúng hạn","Trễ hạn")) -> Đúng hạn | F5: 4.4.6 | G5: 3 | H5: S8
A6: M4 | B6: Hoàn thành kiểm thử hệ thống, bản phát hành sẵn sàng kiểm thử chấp nhận | C6: 46576 | D6: 46583 | E6: =IF(D6="","Không có hạn",IF(C6<=D6,"Đúng hạn","Trễ hạn")) -> Đúng hạn | F6: 1.4.9, 2.4.9, 2.4.10, 3.4.12, 4.4.5, 4.4.6 | H6: S8
A7: M9 | B7: Chủ đầu tư nghiệm thu phần bán hàng trên sàn thương mại điện tử theo yêu cầu thay đổi CR01 | C7: 46595 | D7: 46595 | E7: =IF(D7="","Không có hạn",IF(C7<=D7,"Đúng hạn","Trễ hạn")) -> Đúng hạn | F7: 5.4.5, 5.5.1 | G7: 6 | H7: S9
A8: M5 | B8: Hoàn thành kiểm thử chấp nhận và kiểm thử vận hành cùng Chủ đầu tư | C8: 46595 | D8: 46596 | E8: =IF(D8="","Không có hạn",IF(C8<=D8,"Đúng hạn","Trễ hạn")) -> Đúng hạn | F8: 1.4.11, 2.4.12, 3.4.13 | H8: S9
A9: M6 | B9: Hệ thống đưa vào vận hành (cut over) và được nghiệm thu | C9: 46597 | D9: 46597 | E9: =IF(D9="","Không có hạn",IF(C9<=D9,"Đúng hạn","Trễ hạn")) -> Đúng hạn | F9: Ngày cố định | G9: 4 | H9: S9
A10: M7 | B10: Nhà thầu nộp bảo lãnh bảo hành, bàn giao mã nguồn và hệ thống | C10: 46597 | D10: 46597 | E10: =IF(D10="","Không có hạn",IF(C10<=D10,"Đúng hạn","Trễ hạn")) -> Đúng hạn | F10: 1.5.3, 3.5.4 | G10: 5 | H10: S9
A11: M8 | B11: Đóng dự án, báo cáo tổng kết và bài học kinh nghiệm được lập, hồ sơ dự án được lưu trữ | C11: 46603 | D11: 46611 | E11: =IF(D11="","Không có hạn",IF(C11<=D11,"Đúng hạn","Trễ hạn")) -> Đúng hạn | F11: 1.1.5 | H11: KT

Sheet Giai_doan
A1: Giai đoạn dự án
A3: Giai đoạn | B3: Từ ngày | C3: Đến ngày | D3: Số ngày làm việc | E3: Số gói | F3: MD | G3: Căn cứ | H3: Gói lá
A4: Khởi động | B4: 46464 | C4: 46491 | D4: =NETWORKDAYS(B4,C4,Tong_quan!$F$4:$F$40) -> 20 | E4: =COUNTIFS(Lich_trinh!$I:$I,A4,Lich_trinh!$E:$E,"?*") -> 4 | F4: 11 | G4: Quyết định của nhóm về giai đoạn Khởi động | H4: 1.1.1, 2.1.1, 3.1.1, 3.1.2
A5: Suốt dự án | B5: 46464 | C5: 46597 | D5: =NETWORKDAYS(B5,C5,Tong_quan!$F$4:$F$40) -> 93 | E5: =COUNTIFS(Lich_trinh!$I:$I,A5,Lich_trinh!$E:$E,"?*") -> 14 | F5: 42 | G5: Gói quản lý dàn trải theo sprint | H5: 1.1.2, 1.1.3, 1.1.4, 2.1.2, 2.1.3, 2.1.4, 3.1.3, 3.1.4, 3.1.5, 3.1.6, 4.1.1, 4.1.2, 4.1.3, 5.1.1
A6: Thực hiện | B6: 46464 | C6: 46597 | D6: =NETWORKDAYS(B6,C6,Tong_quan!$F$4:$F$40) -> 93 | E6: 154 | F6: 678 | G6: S1, S2, S3, S4, S5, S6, S7, S8, S9 | H6: 154 gói theo sprint, xem Lich_trinh
A7: Kết thúc | B7: 46598 | C7: 46611 | D7: =NETWORKDAYS(B7,C7,Tong_quan!$F$4:$F$40) -> 10 | E7: =COUNTIFS(Lich_trinh!$I:$I,A7,Lich_trinh!$E:$E,"?*") -> 1 | F7: 2 | G7: 10 ngày làm việc sau cut over | H7: 1.1.5
A8: Tổng | F8: =SUM(F4:F7) -> 733
A10: Ngày đóng dự án (hết giai đoạn Kết thúc): 12/08/2027. Gói quản lý dự án không gắn sprint phát triển, không nằm trong mục tiêu, sản phẩm trình diễn của sprint. Gói Kết thúc không tính vào dự trữ đến cut over.

Sheet Phan_bo
A1: Mã thành viên | B1: Họ tên | C1: Sprint | D1: MD kế hoạch | E1: Quỹ thời gian, MD | F1: Tỷ lệ
A2: dat | B2: Trần Bá Đạt | C2: S1 | D2: 8.76 | E2: 10 | F2: =IF(E2=0,0,D2/E2) -> 0.876
A3: dat | B3: Trần Bá Đạt | C3: S2 | D3: 8.79 | E3: 10 | F3: =IF(E3=0,0,D3/E3) -> 0.879
A4: dat | B4: Trần Bá Đạt | C4: S3 | D4: 11.74 | E4: 13 | F4: =IF(E4=0,0,D4/E4) -> 0.90307692
A5: dat | B5: Trần Bá Đạt | C5: S4 | D5: 8.93 | E5: 10 | F5: =IF(E5=0,0,D5/E5) -> 0.893
A6: dat | B6: Trần Bá Đạt | C6: S5 | D6: 5.02 | E6: 10 | F6: =IF(E6=0,0,D6/E6) -> 0.502
A7: dat | B7: Trần Bá Đạt | C7: S6 | D7: 4.52 | E7: 10 | F7: =IF(E7=0,0,D7/E7) -> 0.452
A8: dat | B8: Trần Bá Đạt | C8: S7 | D8: 5.52 | E8: 7 | F8: =IF(E8=0,0,D8/E8) -> 0.78857143
A9: dat | B9: Trần Bá Đạt | C9: S8 | D9: 6.53 | E9: 8 | F9: =IF(E9=0,0,D9/E9) -> 0.81625
A10: dat | B10: Trần Bá Đạt | C10: S9 | D10: 4.52 | E10: 6 | F10: =IF(E10=0,0,D10/E10) -> 0.75333333
A11: dat | B11: Trần Bá Đạt | C11: KT | D11: 2 | E11: 2 | F11: =IF(E11=0,0,D11/E11) -> 1
A12: tuananh | B12: Phạm Tuấn Anh | C12: S1 | D12: 4 | E12: 10 | F12: =IF(E12=0,0,D12/E12) -> 0.4
A13: tuananh | B13: Phạm Tuấn Anh | C13: S2 | D13: 5 | E13: 10 | F13: =IF(E13=0,0,D13/E13) -> 0.5
... A110: D4 | B110: Trương Quốc Việt | C110: S9 | D110: 5 | E110: 6 | F110: =IF(E110=0,0,D110/E110) -> 0.83333333

Sheet Tai_nguon
A1: Tải công việc theo thành viên và sprint, MD
A3: Mã | B3: Họ tên | C3: S1 | D3: S2 | E3: S3 | F3: S4 | G3: S5 | H3: S6 | I3: S7 | J3: S8 | K3: S9 | L3: KT | M3: Tổng MD | N3: Tổng quỹ | O3: Tỷ lệ
A4: dat | B4: Trần Bá Đạt | C4: =SUMIFS(Phan_bo!$D:$D,Phan_bo!$A:$A,$A4,Phan_bo!$C:$C,C$3) -> 8.76 | D4: =SUMIFS(Phan_bo!$D:$D,Phan_bo!$A:$A,$A4,Phan_bo!$C:$C,D$3) -> 8.79 | E4: =SUMIFS(Phan_bo!$D:$D,Phan_bo!$A:$A,$A4,Phan_bo!$C:$C,E$3) -> 11.74 | F4: =SUMIFS(Phan_bo!$D:$D,Phan_bo!$A:$A,$A4,Phan_bo!$C:$C,F$3) -> 8.93 | G4: =SUMIFS(Phan_bo!$D:$D,Phan_bo!$A:$A,$A4,Phan_bo!$C:$C,G$3) -> 5.02 | H4: =SUMIFS(Phan_bo!$D:$D,Phan_bo!$A:$A,$A4,Phan_bo!$C:$C,H$3) -> 4.52 | I4: =SUMIFS(Phan_bo!$D:$D,Phan_bo!$A:$A,$A4,Phan_bo!$C:$C,I$3) -> 5.52 | J4: =SUMIFS(Phan_bo!$D:$D,Phan_bo!$A:$A,$A4,Phan_bo!$C:$C,J$3) -> 6.53 | ... L4: =SUMIFS(Phan_bo!$D:$D,Phan_bo!$A:$A,$A4,Phan_bo!$C:$C,L$3) -> 2 | M4: =SUM(C4:L4) -> 66.33 | N4: =SUMIFS(Phan_bo!$E:$E,Phan_bo!$A:$A,$A4) -> 86 | O4: =IF(N4=0,0,M4/N4) -> 0.77127907
A5: tuananh | B5: Phạm Tuấn Anh | C5: =SUMIFS(Phan_bo!$D:$D,Phan_bo!$A:$A,$A5,Phan_bo!$C:$C,C$3) -> 4 | D5: =SUMIFS(Phan_bo!$D:$D,Phan_bo!$A:$A,$A5,Phan_bo!$C:$C,D$3) -> 5 | E5: =SUMIFS(Phan_bo!$D:$D,Phan_bo!$A:$A,$A5,Phan_bo!$C:$C,E$3) -> 7 | F5: =SUMIFS(Phan_bo!$D:$D,Phan_bo!$A:$A,$A5,Phan_bo!$C:$C,F$3) -> 11.62 | G5: =SUMIFS(Phan_bo!$D:$D,Phan_bo!$A:$A,$A5,Phan_bo!$C:$C,G$3) -> 8.38 | H5: =SUMIFS(Phan_bo!$D:$D,Phan_bo!$A:$A,$A5,Phan_bo!$C:$C,H$3) -> 9 | I5: =SUMIFS(Phan_bo!$D:$D,Phan_bo!$A:$A,$A5,Phan_bo!$C:$C,I$3) -> 0 | J5: =SUMIFS(Phan_bo!$D:$D,Phan_bo!$A:$A,$A5,Phan_bo!$C:$C,J$3) -> 0 | ... L5: =SUMIFS(Phan_bo!$D:$D,Phan_bo!$A:$A,$A5,Phan_bo!$C:$C,L$3) -> 0 | M5: =SUM(C5:L5) -> 50 | N5: =SUMIFS(Phan_bo!$E:$E,Phan_bo!$A:$A,$A5) -> 69 | O5: =IF(N5=0,0,M5/N5) -> 0.72463768
A6: minh | B6: Vũ Đức Minh | C6: =SUMIFS(Phan_bo!$D:$D,Phan_bo!$A:$A,$A6,Phan_bo!$C:$C,C$3) -> 9 | D6: =SUMIFS(Phan_bo!$D:$D,Phan_bo!$A:$A,$A6,Phan_bo!$C:$C,D$3) -> 10 | E6: =SUMIFS(Phan_bo!$D:$D,Phan_bo!$A:$A,$A6,Phan_bo!$C:$C,E$3) -> 11 | F6: =SUMIFS(Phan_bo!$D:$D,Phan_bo!$A:$A,$A6,Phan_bo!$C:$C,F$3) -> 8.88 | G6: =SUMIFS(Phan_bo!$D:$D,Phan_bo!$A:$A,$A6,Phan_bo!$C:$C,G$3) -> 8.29 | H6: =SUMIFS(Phan_bo!$D:$D,Phan_bo!$A:$A,$A6,Phan_bo!$C:$C,H$3) -> 4.83 | I6: =SUMIFS(Phan_bo!$D:$D,Phan_bo!$A:$A,$A6,Phan_bo!$C:$C,I$3) -> 0 | J6: =SUMIFS(Phan_bo!$D:$D,Phan_bo!$A:$A,$A6,Phan_bo!$C:$C,J$3) -> 2 | ... L6: =SUMIFS(Phan_bo!$D:$D,Phan_bo!$A:$A,$A6,Phan_bo!$C:$C,L$3) -> 0 | M6: =SUM(C6:L6) -> 58 | N6: =SUMIFS(Phan_bo!$E:$E,Phan_bo!$A:$A,$A6) -> 71 | O6: =IF(N6=0,0,M6/N6) -> 0.81690141
A7: toan | B7: Ninh Đức Toàn | C7: =SUMIFS(Phan_bo!$D:$D,Phan_bo!$A:$A,$A7,Phan_bo!$C:$C,C$3) -> 5.86 | D7: =SUMIFS(Phan_bo!$D:$D,Phan_bo!$A:$A,$A7,Phan_bo!$C:$C,D$3) -> 9.14 | E7: =SUMIFS(Phan_bo!$D:$D,Phan_bo!$A:$A,$A7,Phan_bo!$C:$C,E$3) -> 12.25 | F7: =SUMIFS(Phan_bo!$D:$D,Phan_bo!$A:$A,$A7,Phan_bo!$C:$C,F$3) -> 9.45 | G7: =SUMIFS(Phan_bo!$D:$D,Phan_bo!$A:$A,$A7,Phan_bo!$C:$C,G$3) -> 9.3 | H7: =SUMIFS(Phan_bo!$D:$D,Phan_bo!$A:$A,$A7,Phan_bo!$C:$C,H$3) -> 9.5 | I7: =SUMIFS(Phan_bo!$D:$D,Phan_bo!$A:$A,$A7,Phan_bo!$C:$C,I$3) -> 2 | J7: =SUMIFS(Phan_bo!$D:$D,Phan_bo!$A:$A,$A7,Phan_bo!$C:$C,J$3) -> 0 | ... L7: =SUMIFS(Phan_bo!$D:$D,Phan_bo!$A:$A,$A7,Phan_bo!$C:$C,L$3) -> 0 | M7: =SUM(C7:L7) -> 66.5 | N7: =SUMIFS(Phan_bo!$E:$E,Phan_bo!$A:$A,$A7) -> 76 | O7: =IF(N7=0,0,M7/N7) -> 0.875
A8: lien | B8: Nguyễn Thị Phương Liên | C8: =SUMIFS(Phan_bo!$D:$D,Phan_bo!$A:$A,$A8,Phan_bo!$C:$C,C$3) -> 10 | D8: =SUMIFS(Phan_bo!$D:$D,Phan_bo!$A:$A,$A8,Phan_bo!$C:$C,D$3) -> 10 | E8: =SUMIFS(Phan_bo!$D:$D,Phan_bo!$A:$A,$A8,Phan_bo!$C:$C,E$3) -> 11 | F8: =SUMIFS(Phan_bo!$D:$D,Phan_bo!$A:$A,$A8,Phan_bo!$C:$C,F$3) -> 7.96 | G8: =SUMIFS(Phan_bo!$D:$D,Phan_bo!$A:$A,$A8,Phan_bo!$C:$C,G$3) -> 8.04 | H8: =SUMIFS(Phan_bo!$D:$D,Phan_bo!$A:$A,$A8,Phan_bo!$C:$C,H$3) -> 9.5 | I8: =SUMIFS(Phan_bo!$D:$D,Phan_bo!$A:$A,$A8,Phan_bo!$C:$C,I$3) -> 7 | J8: =SUMIFS(Phan_bo!$D:$D,Phan_bo!$A:$A,$A8,Phan_bo!$C:$C,J$3) -> 3.5 | ... L8: =SUMIFS(Phan_bo!$D:$D,Phan_bo!$A:$A,$A8,Phan_bo!$C:$C,L$3) -> 0 | M8: =SUM(C8:L8) -> 72.5 | N8: =SUMIFS(Phan_bo!$E:$E,Phan_bo!$A:$A,$A8) -> 83 | O8: =IF(N8=0,0,M8/N8) -> 0.87349398
A9: K | B9: Nguyễn Hoàng Nam | C9: =SUMIFS(Phan_bo!$D:$D,Phan_bo!$A:$A,$A9,Phan_bo!$C:$C,C$3) -> 9.67 | D9: =SUMIFS(Phan_bo!$D:$D,Phan_bo!$A:$A,$A9,Phan_bo!$C:$C,D$3) -> 9 | E9: =SUMIFS(Phan_bo!$D:$D,Phan_bo!$A:$A,$A9,Phan_bo!$C:$C,E$3) -> 12 | F9: =SUMIFS(Phan_bo!$D:$D,Phan_bo!$A:$A,$A9,Phan_bo!$C:$C,F$3) -> 9.5 | G9: =SUMIFS(Phan_bo!$D:$D,Phan_bo!$A:$A,$A9,Phan_bo!$C:$C,G$3) -> 7 | H9: =SUMIFS(Phan_bo!$D:$D,Phan_bo!$A:$A,$A9,Phan_bo!$C:$C,H$3) -> 9.5 | I9: =SUMIFS(Phan_bo!$D:$D,Phan_bo!$A:$A,$A9,Phan_bo!$C:$C,I$3) -> 0 | J9: =SUMIFS(Phan_bo!$D:$D,Phan_bo!$A:$A,$A9,Phan_bo!$C:$C,J$3) -> 7.5 | ... L9: =SUMIFS(Phan_bo!$D:$D,Phan_bo!$A:$A,$A9,Phan_bo!$C:$C,L$3) -> 0 | M9: =SUM(C9:L9) -> 70.67 | N9: =SUMIFS(Phan_bo!$E:$E,Phan_bo!$A:$A,$A9) -> 80 | O9: =IF(N9=0,0,M9/N9) -> 0.883375
A10: D1 | B10: Lê Quang Huy | C10: =SUMIFS(Phan_bo!$D:$D,Phan_bo!$A:$A,$A10,Phan_bo!$C:$C,C$3) -> 4 | D10: =SUMIFS(Phan_bo!$D:$D,Phan_bo!$A:$A,$A10,Phan_bo!$C:$C,D$3) -> 9 | E10: =SUMIFS(Phan_bo!$D:$D,Phan_bo!$A:$A,$A10,Phan_bo!$C:$C,E$3) -> 9 | F10: =SUMIFS(Phan_bo!$D:$D,Phan_bo!$A:$A,$A10,Phan_bo!$C:$C,F$3) -> 8.35 | G10: =SUMIFS(Phan_bo!$D:$D,Phan_bo!$A:$A,$A10,Phan_bo!$C:$C,G$3) -> 7.15 | H10: =SUMIFS(Phan_bo!$D:$D,Phan_bo!$A:$A,$A10,Phan_bo!$C:$C,H$3) -> 10 | I10: =SUMIFS(Phan_bo!$D:$D,Phan_bo!$A:$A,$A10,Phan_bo!$C:$C,I$3) -> 10 | J10: =SUMIFS(Phan_bo!$D:$D,Phan_bo!$A:$A,$A10,Phan_bo!$C:$C,J$3) -> 2 | ... L10: =SUMIFS(Phan_bo!$D:$D,Phan_bo!$A:$A,$A10,Phan_bo!$C:$C,L$3) -> 0 | M10: =SUM(C10:L10) -> 67.5 | N10: =SUMIFS(Phan_bo!$E:$E,Phan_bo!$A:$A,$A10) -> 85 | O10: =IF(N10=0,0,M10/N10) -> 0.79411765
A11: D2 | B11: Đỗ Minh Quân | C11: =SUMIFS(Phan_bo!$D:$D,Phan_bo!$A:$A,$A11,Phan_bo!$C:$C,C$3) -> 0 | D11: =SUMIFS(Phan_bo!$D:$D,Phan_bo!$A:$A,$A11,Phan_bo!$C:$C,D$3) -> 4 | E11: =SUMIFS(Phan_bo!$D:$D,Phan_bo!$A:$A,$A11,Phan_bo!$C:$C,E$3) -> 13.83 | F11: =SUMIFS(Phan_bo!$D:$D,Phan_bo!$A:$A,$A11,Phan_bo!$C:$C,F$3) -> 10.27 | G11: =SUMIFS(Phan_bo!$D:$D,Phan_bo!$A:$A,$A11,Phan_bo!$C:$C,G$3) -> 7.9 | H11: =SUMIFS(Phan_bo!$D:$D,Phan_bo!$A:$A,$A11,Phan_bo!$C:$C,H$3) -> 6 | I11: =SUMIFS(Phan_bo!$D:$D,Phan_bo!$A:$A,$A11,Phan_bo!$C:$C,I$3) -> 9 | J11: =SUMIFS(Phan_bo!$D:$D,Phan_bo!$A:$A,$A11,Phan_bo!$C:$C,J$3) -> 3 | ... L11: =SUMIFS(Phan_bo!$D:$D,Phan_bo!$A:$A,$A11,Phan_bo!$C:$C,L$3) -> 0 | M11: =SUM(C11:L11) -> 64 | N11: =SUMIFS(Phan_bo!$E:$E,Phan_bo!$A:$A,$A11) -> 77 | O11: =IF(N11=0,0,M11/N11) -> 0.83116883
A12: D3 | B12: Bùi Anh Tuấn | C12: =SUMIFS(Phan_bo!$D:$D,Phan_bo!$A:$A,$A12,Phan_bo!$C:$C,C$3) -> 3 | D12: =SUMIFS(Phan_bo!$D:$D,Phan_bo!$A:$A,$A12,Phan_bo!$C:$C,D$3) -> 3.83 | E12: =SUMIFS(Phan_bo!$D:$D,Phan_bo!$A:$A,$A12,Phan_bo!$C:$C,E$3) -> 12.17 | F12: =SUMIFS(Phan_bo!$D:$D,Phan_bo!$A:$A,$A12,Phan_bo!$C:$C,F$3) -> 8.25 | G12: =SUMIFS(Phan_bo!$D:$D,Phan_bo!$A:$A,$A12,Phan_bo!$C:$C,G$3) -> 6.25 | H12: =SUMIFS(Phan_bo!$D:$D,Phan_bo!$A:$A,$A12,Phan_bo!$C:$C,H$3) -> 7 | I12: =SUMIFS(Phan_bo!$D:$D,Phan_bo!$A:$A,$A12,Phan_bo!$C:$C,I$3) -> 9 | J12: =SUMIFS(Phan_bo!$D:$D,Phan_bo!$A:$A,$A12,Phan_bo!$C:$C,J$3) -> 6.5 | ... L12: =SUMIFS(Phan_bo!$D:$D,Phan_bo!$A:$A,$A12,Phan_bo!$C:$C,L$3) -> 0 | M12: =SUM(C12:L12) -> 59.5 | N12: =SUMIFS(Phan_bo!$E:$E,Phan_bo!$A:$A,$A12) -> 86 | O12: =IF(N12=0,0,M12/N12) -> 0.69186047
A13: Q1 | B13: Trần Thu Hà | C13: =SUMIFS(Phan_bo!$D:$D,Phan_bo!$A:$A,$A13,Phan_bo!$C:$C,C$3) -> 0 | D13: =SUMIFS(Phan_bo!$D:$D,Phan_bo!$A:$A,$A13,Phan_bo!$C:$C,D$3) -> 3 | E13: =SUMIFS(Phan_bo!$D:$D,Phan_bo!$A:$A,$A13,Phan_bo!$C:$C,E$3) -> 8.75 | F13: =SUMIFS(Phan_bo!$D:$D,Phan_bo!$A:$A,$A13,Phan_bo!$C:$C,F$3) -> 11.16 | G13: =SUMIFS(Phan_bo!$D:$D,Phan_bo!$A:$A,$A13,Phan_bo!$C:$C,G$3) -> 9.09 | H13: =SUMIFS(Phan_bo!$D:$D,Phan_bo!$A:$A,$A13,Phan_bo!$C:$C,H$3) -> 4 | I13: =SUMIFS(Phan_bo!$D:$D,Phan_bo!$A:$A,$A13,Phan_bo!$C:$C,I$3) -> 7 | J13: =SUMIFS(Phan_bo!$D:$D,Phan_bo!$A:$A,$A13,Phan_bo!$C:$C,J$3) -> 1 | ... L13: =SUMIFS(Phan_bo!$D:$D,Phan_bo!$A:$A,$A13,Phan_bo!$C:$C,L$3) -> 0 | M13: =SUM(C13:L13) -> 49.5 | N13: =SUMIFS(Phan_bo!$E:$E,Phan_bo!$A:$A,$A13) -> 70 | O13: =IF(N13=0,0,M13/N13) -> 0.70714286
A14: Q2 | B14: Phạm Ngọc Anh | C14: =SUMIFS(Phan_bo!$D:$D,Phan_bo!$A:$A,$A14,Phan_bo!$C:$C,C$3) -> 0 | D14: =SUMIFS(Phan_bo!$D:$D,Phan_bo!$A:$A,$A14,Phan_bo!$C:$C,D$3) -> 0 | E14: =SUMIFS(Phan_bo!$D:$D,Phan_bo!$A:$A,$A14,Phan_bo!$C:$C,E$3) -> 6 | F14: =SUMIFS(Phan_bo!$D:$D,Phan_bo!$A:$A,$A14,Phan_bo!$C:$C,F$3) -> 9.73 | G14: =SUMIFS(Phan_bo!$D:$D,Phan_bo!$A:$A,$A14,Phan_bo!$C:$C,G$3) -> 9.25 | H14: =SUMIFS(Phan_bo!$D:$D,Phan_bo!$A:$A,$A14,Phan_bo!$C:$C,H$3) -> 7.02 | I14: =SUMIFS(Phan_bo!$D:$D,Phan_bo!$A:$A,$A14,Phan_bo!$C:$C,I$3) -> 9 | J14: =SUMIFS(Phan_bo!$D:$D,Phan_bo!$A:$A,$A14,Phan_bo!$C:$C,J$3) -> 1 | ... L14: =SUMIFS(Phan_bo!$D:$D,Phan_bo!$A:$A,$A14,Phan_bo!$C:$C,L$3) -> 0 | M14: =SUM(C14:L14) -> 50 | N14: =SUMIFS(Phan_bo!$E:$E,Phan_bo!$A:$A,$A14) -> 63 | O14: =IF(N14=0,0,M14/N14) -> 0.79365079
A15: D4 | B15: Trương Quốc Việt | C15: =SUMIFS(Phan_bo!$D:$D,Phan_bo!$A:$A,$A15,Phan_bo!$C:$C,C$3) -> 0 | D15: =SUMIFS(Phan_bo!$D:$D,Phan_bo!$A:$A,$A15,Phan_bo!$C:$C,D$3) -> 0 | E15: =SUMIFS(Phan_bo!$D:$D,Phan_bo!$A:$A,$A15,Phan_bo!$C:$C,E$3) -> 12.83 | F15: =SUMIFS(Phan_bo!$D:$D,Phan_bo!$A:$A,$A15,Phan_bo!$C:$C,F$3) -> 10.17 | G15: =SUMIFS(Phan_bo!$D:$D,Phan_bo!$A:$A,$A15,Phan_bo!$C:$C,G$3) -> 10 | H15: =SUMIFS(Phan_bo!$D:$D,Phan_bo!$A:$A,$A15,Phan_bo!$C:$C,H$3) -> 10 | I15: =SUMIFS(Phan_bo!$D:$D,Phan_bo!$A:$A,$A15,Phan_bo!$C:$C,I$3) -> 3 | J15: =SUMIFS(Phan_bo!$D:$D,Phan_bo!$A:$A,$A15,Phan_bo!$C:$C,J$3) -> 7.5 | ... L15: =SUMIFS(Phan_bo!$D:$D,Phan_bo!$A:$A,$A15,Phan_bo!$C:$C,L$3) -> 0 | M15: =SUM(C15:L15) -> 58.5 | N15: =SUMIFS(Phan_bo!$E:$E,Phan_bo!$A:$A,$A15) -> 62 | O15: =IF(N15=0,0,M15/N15) -> 0.94354839
A17: Ô đỏ: vượt quỹ thời gian của sprint. Ô vàng: được huy động trong sprint nhưng dùng dưới 30% quỹ của sprint. Cột KT: MD giai đoạn Kết thúc sau cut over, quỹ theo tỷ lệ huy động giai đoạn Kết thúc của thành viên.

Sheet Nhu_cau
A1: Nhu cầu nhân lực theo loại công việc và sprint, MD
A3: Sprint | B3: BA | C3: DEV | D3: DEVOPS | E3: PM | F3: QA | G3: Tổng MD | H3: Quỹ huy động, MD | I3: Tỷ lệ sử dụng
A4: S1 | B4: 21 | C4: 25 | D4: 0.86 | E4: 7.43 | F4: 0 | G4: =SUM(B4:F4) -> 54.29 | H4: =SUMIFS(Phan_bo!$E:$E,Phan_bo!$C:$C,$A4) -> 80 | I4: =IF(H4=0,0,G4/H4) -> 0.678625
A5: S2 | B5: 19.36 | C5: 32.83 | D5: 8.14 | E5: 8.43 | F5: 3 | G5: =SUM(B5:F5) -> 71.76 | H5: =SUMIFS(Phan_bo!$E:$E,Phan_bo!$C:$C,$A5) -> 100 | I5: =IF(H5=0,0,G5/H5) -> 0.7176
A6: S3 | B6: 23.64 | C6: 84.08 | D6: 0 | E6: 5.1 | F6: 14.75 | G6: =SUM(B6:F6) -> 127.57 | H6: =SUMIFS(Phan_bo!$E:$E,Phan_bo!$C:$C,$A6) -> 156 | I6: =IF(H6=0,0,G6/H6) -> 0.81775641
A7: S4 | B7: 2 | C7: 67.79 | D7: 1 | E7: 5.93 | F7: 37.55 | G7: =SUM(B7:F7) -> 114.27 | H7: =SUMIFS(Phan_bo!$E:$E,Phan_bo!$C:$C,$A7) -> 120 | I7: =IF(H7=0,0,G7/H7) -> 0.95225
A8: S5 | B8: 3 | C8: 41.3 | D8: 6 | E8: 5.02 | F8: 40.35 | G8: =SUM(B8:F8) -> 95.67 | H8: =SUMIFS(Phan_bo!$E:$E,Phan_bo!$C:$C,$A8) -> 120 | I8: =IF(H8=0,0,G8/H8) -> 0.79725
A9: S6 | B9: 14 | C9: 40 | D9: 4 | E9: 4.52 | F9: 28.35 | G9: =SUM(B9:F9) -> 90.87 | H9: =SUMIFS(Phan_bo!$E:$E,Phan_bo!$C:$C,$A9) -> 120 | I9: =IF(H9=0,0,G9/H9) -> 0.75725
A10: S7 | B10: 4 | C10: 24 | D10: 9 | E10: 4.52 | F10: 20 | G10: =SUM(B10:F10) -> 61.52 | H10: =SUMIFS(Phan_bo!$E:$E,Phan_bo!$C:$C,$A10) -> 69 | I10: =IF(H10=0,0,G10/H10) -> 0.8915942
A11: S8 | B11: 13 | C11: 10 | D11: 11 | E11: 4.53 | F11: 2 | G11: =SUM(B11:F11) -> 40.53 | H11: =SUMIFS(Phan_bo!$E:$E,Phan_bo!$C:$C,$A11) -> 53 | I11: =IF(H11=0,0,G11/H11) -> 0.76471698
A12: S9 | B12: 3 | C12: 34 | D12: 2 | E12: 4.52 | F12: 31 | G12: =SUM(B12:F12) -> 74.52 | H12: =SUMIFS(Phan_bo!$E:$E,Phan_bo!$C:$C,$A12) -> 88 | I12: =IF(H12=0,0,G12/H12) -> 0.84681818
A13: KT | B13: 0 | C13: 0 | D13: 0 | E13: 2 | F13: 0 | G13: =SUM(B13:F13) -> 2 | H13: =SUMIFS(Phan_bo!$E:$E,Phan_bo!$C:$C,$A13) -> 2 | I13: =IF(H13=0,0,G13/H13) -> 1
A14: Tổng | B14: =SUM(B4:B13) -> 103 | C14: =SUM(C4:C13) -> 359 | D14: =SUM(D4:D13) -> 42 | E14: =SUM(E4:E13) -> 52 | F14: =SUM(F4:F13) -> 177 | G14: =SUM(G4:G13) -> 733 | H14: =SUM(H4:H13) -> 908 | I14: =IF(H14=0,0,G14/H14) -> 0.80726872
A16: MD từng loại công việc theo ngày thực hiện trong lịch đã xếp nguồn lực. So sánh với quỹ huy động để đề xuất tu_sprint, den_sprint của từng vị trí.

Sheet Cam_ket
A1: Cam kết đầu vào của Chủ đầu tư
A3: Mã | B3: Nội dung cam kết | C3: Hạn (cuối khoảng nếu là khoảng tham gia) | D3: Gói phụ thuộc | E3: Bắt đầu sớm nhất | F3: Trạng thái | G3: Đầu khoảng tham gia | H3: Kết thúc muộn nhất
A4: CK1 | B4: Tài liệu đặc tả giao diện trao đổi dữ liệu của Main System | C4: 46491 | D4: 4.2.5 | E4: 46491 | F4: =IF(C4="","Không có hạn",IF(D4="","Chưa gắn gói",IF(E4>=C4,"Đạt","Bắt đầu trước hạn"))) -> Đạt
A5: CK2 | B5: Môi trường thử của Main System | C5: 46527 | D5: 4.4.3 | E5: 46533 | F5: =IF(C5="","Không có hạn",IF(D5="","Chưa gắn gói",IF(E5>=C5,"Đạt","Bắt đầu trước hạn"))) -> Đạt
A6: CK3 | B6: Dữ liệu sản phẩm, tồn kho phục vụ chuyển đổi theo định dạng thống nhất (nhà thầu đề nghị, HSMT không quy định thời hạn) | C6: 46548 | D6: 4.5.3 | E6: 46549 | F6: =IF(C6="","Không có hạn",IF(D6="","Chưa gắn gói",IF(E6>=C6,"Đạt","Bắt đầu trước hạn"))) -> Đạt
A7: CK4 | B7: Bộ nhận diện thương hiệu, hình ảnh và nội dung sản phẩm (nhà thầu đề nghị, HSMT không quy định thời hạn) | C7: 46548 | D7: 4.5.4 | E7: 46554 | F7: =IF(C7="","Không có hạn",IF(D7="","Chưa gắn gói",IF(E7>=C7,"Đạt","Bắt đầu trước hạn"))) -> Đạt
A8: CK5 | B8: Chủ sản phẩm có thẩm quyền quyết định yêu cầu nghiệp vụ, làm rõ yêu cầu 2-3 buổi mỗi tuần trong sprint 1-3, dự demo cuối mỗi sprint | D8: 3.2.5 | E8: 46511 | F8: =IF(C8="","Không có hạn",IF(D8="","Chưa gắn gói",IF(E8>=C8,"Đạt","Bắt đầu trước hạn"))) -> Không có hạn
A9: CK6 | B9: Người dùng nghiệp vụ tham gia kiểm thử chấp nhận trong khoảng 16/07 đến 27/07/2027 | C9: 46595 | D9: 1.4.11, 2.4.12, 3.4.13 | E9: 46584 | F9: =IF(AND(E9>=G9,H9<=C9),"Trong khoảng cam kết","Ngoài khoảng cam kết") -> Trong khoảng cam kết | G9: 46584 | H9: 46595
A10: CK7 | B10: Hạ tầng vận hành chính thức gồm máy chủ, đường truyền và phần mềm nền (nhà thầu đề nghị bàn giao sớm hơn thời hạn chậm nhất 10/06/2027 của HSMT) | C10: 46527 | D10: 4.5.1 | E10: 46527 | F10: =IF(C10="","Không có hạn",IF(D10="","Chưa gắn gói",IF(E10>=C10,"Đạt","Bắt đầu trước hạn"))) -> Đạt
A11: CK8 | B11: Chủ đầu tư hoàn thành thay đổi phía Main System phục vụ trao đổi dữ liệu với hệ thống mới (phân định tại mục 3.5 Chương V của HSMT) | C11: 46527 | D11: 4.4.3 | E11: 46533 | F11: =IF(C11="","Không có hạn",IF(D11="","Chưa gắn gói",IF(E11>=C11,"Đạt","Bắt đầu trước hạn"))) -> Đạt
A12: CK9 | B12: Phụ lục hợp đồng 01/2027/PL-ABCW điều chỉnh hợp đồng theo yêu cầu thay đổi CR01 có hiệu lực, bắt đầu phần thay đổi | C12: 46539 | D12: 5.2.1, 5.2.2, 5.2.3, 5.2.4, 5.3.1, 5.3.2, 5.3.3, 5.3.4, 5.3.5, 5.3.6, 5.3.7, 5.4.1, 5.4.2, 5.4.3, 5.4.4, 5.4.5, 5.5.1, 5.5.2, 5.5.3 | E12: 46539 | F12: =IF(C12="","Không có hạn",IF(D12="","Chưa gắn gói",IF(E12>=C12,"Đạt","Bắt đầu trước hạn"))) -> Đạt
A13: CK10 | B13: Tài khoản người bán, khóa truy cập và môi trường thử của sàn thương mại điện tử do Chủ đầu tư đăng ký với đơn vị vận hành sàn | C13: 46548 | D13: 5.3.1, 5.4.2 | E13: 46548 | F13: =IF(C13="","Không có hạn",IF(D13="","Chưa gắn gói",IF(E13>=C13,"Đạt","Bắt đầu trước hạn"))) -> Đạt
A15: Gói có Chủ đầu tư tham gia
A16: Gói | B16: Loại tham gia | C16: Thời lượng tối thiểu, ngày | D16: Bắt đầu | E16: Kết thúc | F16: Số ngày làm việc | G16: Trạng thái
A17: 3.1.2 | B17: Phê duyệt tài liệu | C17: 5 | D17: 46485 | E17: 46491 | F17: =NETWORKDAYS(D17,E17,Tong_quan!$F$4:$F$40) -> 5 | G17: =IF(F17>=C17,"Đủ thời lượng","Thiếu thời lượng") -> Đủ thời lượng
A18: 3.2.5 | B18: Phê duyệt tài liệu | C18: 5 | D18: 46511 | E18: 46513 | F18: =NETWORKDAYS(D18,E18,Tong_quan!$F$4:$F$40) -> 3 | G18: =IF(F18>=C18,"Đủ thời lượng","Thiếu thời lượng") -> Thiếu thời lượng
A19: 4.2.6 | B19: Phê duyệt tài liệu | C19: 5 | D19: 46518 | E19: 46524 | F19: =NETWORKDAYS(D19,E19,Tong_quan!$F$4:$F$40) -> 5 | G19: =IF(F19>=C19,"Đủ thời lượng","Thiếu thời lượng") -> Đủ thời lượng
A20: 4.4.6 | B20: Phê duyệt tài liệu | C20: 5 | D20: 46570 | E20: 46576 | F20: =NETWORKDAYS(D20,E20,Tong_quan!$F$4:$F$40) -> 5 | G20: =IF(F20>=C20,"Đủ thời lượng","Thiếu thời lượng") -> Đủ thời lượng
A21: 3.5.2 | B21: Phê duyệt tài liệu | C21: 5 | D21: 46561 | E21: 46567 | F21: =NETWORKDAYS(D21,E21,Tong_quan!$F$4:$F$40) -> 5 | G21: =IF(F21>=C21,"Đủ thời lượng","Thiếu thời lượng") -> Đủ thời lượng
A22: 1.4.11 | B22: Kiểm thử chấp nhận | C22: 8 | D22: 46584 | E22: 46595 | F22: =NETWORKDAYS(D22,E22,Tong_quan!$F$4:$F$40) -> 8 | G22: =IF(F22>=C22,"Đủ thời lượng","Thiếu thời lượng") -> Đủ thời lượng
A23: 2.4.12 | B23: Kiểm thử chấp nhận | C23: 8 | D23: 46584 | E23: 46595 | F23: =NETWORKDAYS(D23,E23,Tong_quan!$F$4:$F$40) -> 8 | G23: =IF(F23>=C23,"Đủ thời lượng","Thiếu thời lượng") -> Đủ thời lượng
A24: 3.4.13 | B24: Kiểm thử chấp nhận | C24: 8 | D24: 46584 | E24: 46595 | F24: =NETWORKDAYS(D24,E24,Tong_quan!$F$4:$F$40) -> 8 | G24: =IF(F24>=C24,"Đủ thời lượng","Thiếu thời lượng") -> Đủ thời lượng
A25: 5.4.5 | B25: Kiểm thử chấp nhận | C25: 8 | D25: 46584 | E25: 46595 | F25: =NETWORKDAYS(D25,E25,Tong_quan!$F$4:$F$40) -> 8 | G25: =IF(F25>=C25,"Đủ thời lượng","Thiếu thời lượng") -> Đủ thời lượng
A26: 5.2.4 | B26: Phê duyệt tài liệu | C26: 5 | D26: 46549 | E26: 46555 | F26: =NETWORKDAYS(D26,E26,Tong_quan!$F$4:$F$40) -> 5 | G26: =IF(F26>=C26,"Đủ thời lượng","Thiếu thời lượng") -> Đủ thời lượng

Sheet Huong_dan
A1: Hướng dẫn sử dụng master schedule
A2: Sheet Lich_trinh: lịch từng gói WBS, thanh Gantt theo tuần. Mục cha tính bằng công thức từ mục con.
A3: Sheet Sprint: mục tiêu, sản phẩm trình diễn, MD kế hoạch và quỹ thời gian từng sprint.
A4: Sheet Moc: các mốc, ngày dự kiến, hạn, trạng thái, liên kết đợt thanh toán.
A5: Sheet Giai_doan: giai đoạn Khởi động, Thực hiện (các sprint), Kết thúc (sau cut over) và gói quản lý dự án dàn trải suốt dự án.
A6: Sheet Phan_bo và Tai_nguon: MD kế hoạch theo thành viên và sprint, ô đỏ là quá tải, ô vàng là dùng dưới ngưỡng quỹ của sprint huy động.
A7: Sheet Nhu_cau: MD theo loại công việc và sprint so với quỹ huy động, dùng để đề xuất thời gian huy động từng vị trí.
A8: Sheet Cam_ket: hạn đầu vào của Chủ đầu tư và gói phụ thuộc, gói có Chủ đầu tư tham gia (phê duyệt tài liệu, kiểm thử chấp nhận) và thời lượng tối thiểu.
A9: Cách cập nhật: sửa WBS, giao việc hoặc mốc và lập lại lịch theo skill master schedule. Không sửa tay các ô chữ xanh dương.
A10: Nguồn dữ liệu: lịch dự án do công cụ của nhóm lập, tạo lúc 25/10/2026 17:46.
